Workbook

Sheet Legenda
B1: SIMULATORE TOU — IMPOSTA ALLA FONTE vs TASSAZIONE ORDINARIA ULTERIORE (TICINO)
B3: COME SI USA
B4: 1. Nel foglio 'Clienti' compila SOLO le celle gialle (una riga per cliente): profilo, stato civile, comune, salario lordo, salario netto (certificato di salario, cifra 11), imposta alla fonte trattenuta nell'anno e deduzioni effettive.
B5: 2. Il foglio stima l'imposta ordinaria (cantone + comune + IFD) e la confronta con la trattenuta alla fonte: colonna 'Differenza' > 0 = con la TOU si risparmia; il 'Verdetto' applica il margine di neutralità del foglio Parametri.
B6: 3. Per una decisione reale: calcola l'aliquota media esatta con il calcolatore ufficiale (www4.ti.ch > DFE > Divisione delle contribuzioni > Calcolo dell'imposta, oppure swisstaxcalculator.estv.admin.ch) e inseriscila nella colonna 'Override aliquota media TI': se compilata, sostituisce la stima.
B7: 4. Nel foglio 'Parametri' controlla moltiplicatore comunale, deduzioni di riferimento e tariffe: sono tutte celle modificabili.
B9: LEGENDA COLORI
B10: Sfondo GIALLO = cella da compilare · testo BLU = valore inserito a mano · testo NERO = formula (non toccare).
B12: REGOLE TOU IN SINTESI (TICINO)
B13: » Residenti in Ticino tassati alla fonte: TOU OBBLIGATORIA se il reddito lordo da attività dipendente supera CHF 120'000 annui; sotto la soglia è richiedibile su base volontaria.
B14: » Non residenti (quasi-residenti): TOU richiedibile se almeno il 90% dei proventi mondiali (coniuge incluso) è imponibile in Svizzera.
B15: » Termine: richiesta entro il 31 MARZO dell'anno successivo all'anno fiscale. Attenzione: una volta in ordinaria si resta in ordinaria anche per gli anni successivi (scelta di fatto irrevocabile) — valutare la convenienza pluriennale.
... B20: Stima indicativa a scopo di consulenza interna: le tariffe nel foglio Parametri (IFD ed. 2025; scala TI APPROSSIMATIVA) vanno verificate prima di comunicare importi al cliente. Non sostituisce il conteggio ufficiale.

Sheet Parametri
A1: PARAMETRI — TICINO
A3: GENERALI
A4: Anno fiscale | B4: 2026
A5: Moltiplicatore cantonale (%) | B5: 100 | C5: Aliquota cantonale base x 100%
A6: Margine di neutralità verdetto (CHF) | B6: 300 | C6: Sotto questa differenza il verdetto è 'circa neutra'
A7: Soglia TOU obbligatoria residenti (lordo CHF) | B7: 120000 | C7: Fonte: direttiva UIF TI 01.01.2025
A8: Termine richiesta TOU | B8: 31 marzo anno successivo
A10: MOLTIPLICATORI COMUNALI — PERSONE FISICHE (%)
A11: Comune | B11: Molt. PF % | C11: Nota
A12: Lugano | B12: 80 | C12: 2026 approvato (2025: 77) — fonte RSI/CdT
A13: Bellinzona | B13: 93 | C13: DA VERIFICARE
A14: Locarno | B14: 90 | C14: DA VERIFICARE
A15: Mendrisio | B15: 75 | C15: DA VERIFICARE
A16: Chiasso | B16: 100 | C16: DA VERIFICARE
A17: Paradiso | B17: 55 | C17: DA VERIFICARE
A18: Massagno | B18: 65 | C18: DA VERIFICARE
A19: Altro | B19: 80 | C19: media indicativa — sostituire
A21: DEDUZIONI DI RIFERIMENTO (memo — verificare importi anno fiscale)
A22: Pilastro 3a max (dipendente con cassa pensione) | B22: 7258 | C22: 2026 confermato — fonte: UBS/Raiffeisen/AXA, cons. 29.08.2026
A23: Deduzione per figlio — CANTONE (CHF) | B23: 11100 | C23: DA VERIFICARE (art. 34 LT)
A24: Deduzione per figlio — IFD (CHF) | B24: 6700 | C24: DA VERIFICARE (art. 35 LIFD)
A25: Spese formazione max IFD (CHF) | B25: 12900 | C25: memo — DA VERIFICARE
A26: Spese professionali forfait TI (CHF) | B26: 2500 | C26: memo — DA VERIFICARE
A29: TARIFFA IFD — PERSONA SOLA (edizione 2025 — VERIFICARE per il 2026)
A30: Da (CHF) | B30: Aliquota marginale | C30: Imposta base a soglia (CHF)
A31: 0 | B31: 0 | C31: 0
A32: 15200 | B32: 0.0077 | C32: =C31+(A32-A31)*B31 -> 0
A33: 33200 | B33: 0.0088 | C33: =C32+(A33-A32)*B32 -> 138.6
A34: 43500 | B34: 0.0264 | C34: =C33+(A34-A33)*B33 -> 229.24
A35: 58000 | B35: 0.0297 | C35: =C34+(A35-A34)*B34 -> 612.04
A36: 76100 | B36: 0.0594 | C36: =C35+(A36-A35)*B35 -> 1149.61
A37: 82000 | B37: 0.066 | C37: =C36+(A37-A36)*B36 -> 1500.07
A38: 108800 | B38: 0.088 | C38: =C37+(A38-A37)*B37 -> 3268.87
A39: 141500 | B39: 0.11 | C39: =C38+(A39-A38)*B38 -> 6146.47
A40: 184900 | B40: 0.132 | C40: =C39+(A40-A39)*B39 -> 10920.47
A41: Soglia aliquota unica (CHF) | B41: 793400
A42: Aliquota unica sopra soglia | B42: 0.115
A45: TARIFFA IFD — CONIUGATI (edizione 2025 — VERIFICARE per il 2026)
A46: Da (CHF) | B46: Aliquota marginale | C46: Imposta base a soglia (CHF)
A47: 0 | B47: 0 | C47: 0
...

Sheet Clienti
A1: CONFRONTO FONTE vs TOU — compilare solo le celle gialle (colonne A–M e S)
A2: Cliente | B2: Profilo | C2: Stato civile | D2: Comune | E2: Figli a carico | F2: Salario lordo annuo | G2: Salario netto (cert. cifra 11) | H2: Imposta fonte trattenuta (anno) | I2: Pilastro 3a | J2: Spese professionali | K2: Premi assicurativi | L2: Formazione | M2: Altre deduzioni | N2: Ded. figli cantone | O2: Ded. figli IFD | P2: Imponibile cantonale | Q2: Imponibile IFD | R2: Aliquota media TI stimata | S2: Override aliquota media TI | T2: Imposta cantonale base | U2: Cantone + comune | V2: IFD | W2: Totale ordinaria stimata | X2: Aliquota fonte effettiva | Y2: Differenza (fonte − ordinaria) | Z2: TOU obbligatoria? | AA2: Verdetto | AB2: Note
A3: Irina (ESEMPIO — sostituire) | B3: Residente TI | C3: Sola | D3: Lugano | E3: 0 | F3: 95000 | G3: 84500 | H3: 8700 | I3: 7258 | J3: 2500 | K3: 2800 | L3: 0 | M3: 0 | N3: =E3*Parametri!$B$23 -> 0 | O3: =E3*Parametri!$B$24 -> 0 | P3: =MAX(0,G3-SUM(I3:M3)-N3) -> 71942 | Q3: =MAX(0,G3-SUM(I3:M3)-O3) -> 71942 | R3: =IF(P3<=0,0,IF(C3="Coniugati",IF(P3>=Parametri!$B$93,Parametri!$B$94,(VLOOKUP(P3,Parametri!$A$83:$C$92,3,TRUE())+(P3-VLOOKUP(P3,Parametri!$A$83:$C$92,1,TRUE()))*VLOOKUP(P3,Parametri!$A$83:$C$92,2,TRUE()))/P3),IF(P3>=Parametri!$B$77,Parametri!$B$78,(VLOOKUP(P3,Parametri!$A$67:$C$76,3,TRUE())+(P3-VLOOKUP(P3,Parametri!$A$67:$C$76,1,TRUE()))*VLOOKUP(P3,Parametri!$A$67:$C$76,2,TRUE()))/P3))) -> 0.045992327 | T3: =P3*IF(S3="",R3,S3) -> 3308.78 | U3: =T3*(Parametri!$B$5+IFERROR(VLOOKUP(D3,Parametri!$A$12:$B$19,2,FALSE()),VLOOKUP("Altro",Parametri!$A$12:$B$19,2,FALSE())))/100 -> 5955.804 | V3: =IF(Q3<=0,0,IF(C3="Coniugati",IF(Q3>=Parametri!$B$61,Q3*Parametri!$B$62,VLOOKUP(Q3,Parametri!$A$47:$C$60,3,TRUE())+(Q3-VLOOKUP(Q3,Parametri!$A$47:$C$60,1,TRUE()))*VLOOKUP(Q3,Parametri!$A$47:$C$60,2,TRUE())),IF(Q3>=Parametri!$B$41,Q3*Parametri!$B$42,VLOOKUP(Q3,Parametri!$A$31:$C$40,3,TRUE())+(Q3-VLOOKUP(Q3,Parametri!$A$31:$C$40,1,TRUE()))*VLOOKUP(Q3,Parametri!$A$31:$C$40,2,TRUE())))) -> 1026.1174 | W3: =U3+V3 -> 6981.9214 | X3: =IF(F3>0,H3/F3,0) -> 0.091578947 | Y3: =H3-W3 -> 1718.0786 | Z3: =IF(B3="","",IF(B3="Residente TI",IF(F3>Parametri!$B$7,"SÌ (obbligatoria)","no"),"—")) -> no | AA3: =IF(B3="","",IF(B3="Frontaliere nuovo accordo","TOU NON RICHIEDIBILE",IF(Y3>Parametri!$B$6,"TOU CONVIENE",IF(Y3<-Parametri!$B$6,"TOU NON CONVIENE","CIRCA NEUTRA")))) -> TOU CONVIENE | AB3: Valori dimostrativi, non reali
N4: =E4*Parametri!$B$23 -> 0 | O4: =E4*Parametri!$B$24 -> 0 | P4: =MAX(0,G4-SUM(I4:M4)-N4) -> 0 | Q4: =MAX(0,G4-SUM(I4:M4)-O4) -> 0 | R4: =IF(P4<=0,0,IF(C4="Coniugati",IF(P4>=Parametri!$B$93,Parametri!$B$94,(VLOOKUP(P4,Parametri!$A$83:$C$92,3,TRUE())+(P4-VLOOKUP(P4,Parametri!$A$83:$C$92,1,TRUE()))*VLOOKUP(P4,Parametri!$A$83:$C$92,2,TRUE()))/P4),IF(P4>=Parametri!$B$77,Parametri!$B$78,(VLOOKUP(P4,Parametri!$A$67:$C$76,3,TRUE())+(P4-VLOOKUP(P4,Parametri!$A$67:$C$76,1,TRUE()))*VLOOKUP(P4,Parametri!$A$67:$C$76,2,TRUE()))/P4))) -> 0 | T4: =P4*IF(S4="",R4,S4) -> 0 | U4: =T4*(Parametri!$B$5+IFERROR(VLOOKUP(D4,Parametri!$A$12:$B$19,2,FALSE()),VLOOKUP("Altro",Parametri!$A$12:$B$19,2,FALSE())))/100 -> 0 | V4: =IF(Q4<=0,0,IF(C4="Coniugati",IF(Q4>=Parametri!$B$61,Q4*Parametri!$B$62,VLOOKUP(Q4,Parametri!$A$47:$C$60,3,TRUE())+(Q4-VLOOKUP(Q4,Parametri!$A$47:$C$60,1,TRUE()))*VLOOKUP(Q4,Parametri!$A$47:$C$60,2,TRUE())),IF(Q4>=Parametri!$B$41,Q4*Parametri!$B$42,VLOOKUP(Q4,Parametri!$A$31:$C$40,3,TRUE())+(Q4-VLOOKUP(Q4,Parametri!$A$31:$C$40,1,TRUE()))*VLOOKUP(Q4,Parametri!$A$31:$C$40,2,TRUE())))) -> 0 | W4: =U4+V4 -> 0 | X4: =IF(F4>0,H4/F4,0) -> 0 | Y4: =H4-W4 -> 0 | Z4: =IF(B4="","",IF(B4="Residente TI",IF(F4>Parametri!$B$7,"SÌ (obbligatoria)","no"),"—")) | AA4: =IF(B4="","",IF(B4="Frontaliere nuovo accordo","TOU NON RICHIEDIBILE",IF(Y4>Parametri!$B$6,"TOU CONVIENE",IF(Y4<-Parametri!$B$6,"TOU NON CONVIENE","CIRCA NEUTRA"))))
N5: =E5*Parametri!$B$23 -> 0 | O5: =E5*Parametri!$B$24 -> 0 | P5: =MAX(0,G5-SUM(I5:M5)-N5) -> 0 | Q5: =MAX(0,G5-SUM(I5:M5)-O5) -> 0 | R5: =IF(P5<=0,0,IF(C5="Coniugati",IF(P5>=Parametri!$B$93,Parametri!$B$94,(VLOOKUP(P5,Parametri!$A$83:$C$92,3,TRUE())+(P5-VLOOKUP(P5,Parametri!$A$83:$C$92,1,TRUE()))*VLOOKUP(P5,Parametri!$A$83:$C$92,2,TRUE()))/P5),IF(P5>=Parametri!$B$77,Parametri!$B$78,(VLOOKUP(P5,Parametri!$A$67:$C$76,3,TRUE())+(P5-VLOOKUP(P5,Parametri!$A$67:$C$76,1,TRUE()))*VLOOKUP(P5,Parametri!$A$67:$C$76,2,TRUE()))/P5))) -> 0 | T5: =P5*IF(S5="",R5,S5) -> 0 | U5: =T5*(Parametri!$B$5+IFERROR(VLOOKUP(D5,Parametri!$A$12:$B$19,2,FALSE()),VLOOKUP("Altro",Parametri!$A$12:$B$19,2,FALSE())))/100 -> 0 | V5: =IF(Q5<=0,0,IF(C5="Coniugati",IF(Q5>=Parametri!$B$61,Q5*Parametri!$B$62,VLOOKUP(Q5,Parametri!$A$47:$C$60,3,TRUE())+(Q5-VLOOKUP(Q5,Parametri!$A$47:$C$60,1,TRUE()))*VLOOKUP(Q5,Parametri!$A$47:$C$60,2,TRUE())),IF(Q5>=Parametri!$B$41,Q5*Parametri!$B$42,VLOOKUP(Q5,Parametri!$A$31:$C$40,3,TRUE())+(Q5-VLOOKUP(Q5,Parametri!$A$31:$C$40,1,TRUE()))*VLOOKUP(Q5,Parametri!$A$31:$C$40,2,TRUE())))) -> 0 | W5: =U5+V5 -> 0 | X5: =IF(F5>0,H5/F5,0) -> 0 | Y5: =H5-W5 -> 0 | Z5: =IF(B5="","",IF(B5="Residente TI",IF(F5>Parametri!$B$7,"SÌ (obbligatoria)","no"),"—")) | AA5: =IF(B5="","",IF(B5="Frontaliere nuovo accordo","TOU NON RICHIEDIBILE",IF(Y5>Parametri!$B$6,"TOU CONVIENE",IF(Y5<-Parametri!$B$6,"TOU NON CONVIENE","CIRCA NEUTRA"))))
N6: =E6*Parametri!$B$23 -> 0 | O6: =E6*Parametri!$B$24 -> 0 | P6: =MAX(0,G6-SUM(I6:M6)-N6) -> 0 | Q6: =MAX(0,G6-SUM(I6:M6)-O6) -> 0 | R6: =IF(P6<=0,0,IF(C6="Coniugati",IF(P6>=Parametri!$B$93,Parametri!$B$94,(VLOOKUP(P6,Parametri!$A$83:$C$92,3,TRUE())+(P6-VLOOKUP(P6,Parametri!$A$83:$C$92,1,TRUE()))*VLOOKUP(P6,Parametri!$A$83:$C$92,2,TRUE()))/P6),IF(P6>=Parametri!$B$77,Parametri!$B$78,(VLOOKUP(P6,Parametri!$A$67:$C$76,3,TRUE())+(P6-VLOOKUP(P6,Parametri!$A$67:$C$76,1,TRUE()))*VLOOKUP(P6,Parametri!$A$67:$C$76,2,TRUE()))/P6))) -> 0 | T6: =P6*IF(S6="",R6,S6) -> 0 | U6: =T6*(Parametri!$B$5+IFERROR(VLOOKUP(D6,Parametri!$A$12:$B$19,2,FALSE()),VLOOKUP("Altro",Parametri!$A$12:$B$19,2,FALSE())))/100 -> 0 | V6: =IF(Q6<=0,0,IF(C6="Coniugati",IF(Q6>=Parametri!$B$61,Q6*Parametri!$B$62,VLOOKUP(Q6,Parametri!$A$47:$C$60,3,TRUE())+(Q6-VLOOKUP(Q6,Parametri!$A$47:$C$60,1,TRUE()))*VLOOKUP(Q6,Parametri!$A$47:$C$60,2,TRUE())),IF(Q6>=Parametri!$B$41,Q6*Parametri!$B$42,VLOOKUP(Q6,Parametri!$A$31:$C$40,3,TRUE())+(Q6-VLOOKUP(Q6,Parametri!$A$31:$C$40,1,TRUE()))*VLOOKUP(Q6,Parametri!$A$31:$C$40,2,TRUE())))) -> 0 | W6: =U6+V6 -> 0 | X6: =IF(F6>0,H6/F6,0) -> 0 | Y6: =H6-W6 -> 0 | Z6: =IF(B6="","",IF(B6="Residente TI",IF(F6>Parametri!$B$7,"SÌ (obbligatoria)","no"),"—")) | AA6: =IF(B6="","",IF(B6="Frontaliere nuovo accordo","TOU NON RICHIEDIBILE",IF(Y6>Parametri!$B$6,"TOU CONVIENE",IF(Y6<-Parametri!$B$6,"TOU NON CONVIENE","CIRCA NEUTRA"))))
N7: =E7*Parametri!$B$23 -> 0 | O7: =E7*Parametri!$B$24 -> 0 | P7: =MAX(0,G7-SUM(I7:M7)-N7) -> 0 | Q7: =MAX(0,G7-SUM(I7:M7)-O7) -> 0 | R7: =IF(P7<=0,0,IF(C7="Coniugati",IF(P7>=Parametri!$B$93,Parametri!$B$94,(VLOOKUP(P7,Parametri!$A$83:$C$92,3,TRUE())+(P7-VLOOKUP(P7,Parametri!$A$83:$C$92,1,TRUE()))*VLOOKUP(P7,Parametri!$A$83:$C$92,2,TRUE()))/P7),IF(P7>=Parametri!$B$77,Parametri!$B$78,(VLOOKUP(P7,Parametri!$A$67:$C$76,3,TRUE())+(P7-VLOOKUP(P7,Parametri!$A$67:$C$76,1,TRUE()))*VLOOKUP(P7,Parametri!$A$67:$C$76,2,TRUE()))/P7))) -> 0 | T7: =P7*IF(S7="",R7,S7) -> 0 | U7: =T7*(Parametri!$B$5+IFERROR(VLOOKUP(D7,Parametri!$A$12:$B$19,2,FALSE()),VLOOKUP("Altro",Parametri!$A$12:$B$19,2,FALSE())))/100 -> 0 | V7: =IF(Q7<=0,0,IF(C7="Coniugati",IF(Q7>=Parametri!$B$61,Q7*Parametri!$B$62,VLOOKUP(Q7,Parametri!$A$47:$C$60,3,TRUE())+(Q7-VLOOKUP(Q7,Parametri!$A$47:$C$60,1,TRUE()))*VLOOKUP(Q7,Parametri!$A$47:$C$60,2,TRUE())),IF(Q7>=Parametri!$B$41,Q7*Parametri!$B$42,VLOOKUP(Q7,Parametri!$A$31:$C$40,3,TRUE())+(Q7-VLOOKUP(Q7,Parametri!$A$31:$C$40,1,TRUE()))*VLOOKUP(Q7,Parametri!$A$31:$C$40,2,TRUE())))) -> 0 | W7: =U7+V7 -> 0 | X7: =IF(F7>0,H7/F7,0) -> 0 | Y7: =H7-W7 -> 0 | Z7: =IF(B7="","",IF(B7="Residente TI",IF(F7>Parametri!$B$7,"SÌ (obbligatoria)","no"),"—")) | AA7: =IF(B7="","",IF(B7="Frontaliere nuovo accordo","TOU NON RICHIEDIBILE",IF(Y7>Parametri!$B$6,"TOU CONVIENE",IF(Y7<-Parametri!$B$6,"TOU NON CONVIENE","CIRCA NEUTRA"))))
N8: =E8*Parametri!$B$23 -> 0 | O8: =E8*Parametri!$B$24 -> 0 | P8: =MAX(0,G8-SUM(I8:M8)-N8) -> 0 | Q8: =MAX(0,G8-SUM(I8:M8)-O8) -> 0 | R8: =IF(P8<=0,0,IF(C8="Coniugati",IF(P8>=Parametri!$B$93,Parametri!$B$94,(VLOOKUP(P8,Parametri!$A$83:$C$92,3,TRUE())+(P8-VLOOKUP(P8,Parametri!$A$83:$C$92,1,TRUE()))*VLOOKUP(P8,Parametri!$A$83:$C$92,2,TRUE()))/P8),IF(P8>=Parametri!$B$77,Parametri!$B$78,(VLOOKUP(P8,Parametri!$A$67:$C$76,3,TRUE())+(P8-VLOOKUP(P8,Parametri!$A$67:$C$76,1,TRUE()))*VLOOKUP(P8,Parametri!$A$67:$C$76,2,TRUE()))/P8))) -> 0 | T8: =P8*IF(S8="",R8,S8) -> 0 | U8: =T8*(Parametri!$B$5+IFERROR(VLOOKUP(D8,Parametri!$A$12:$B$19,2,FALSE()),VLOOKUP("Altro",Parametri!$A$12:$B$19,2,FALSE())))/100 -> 0 | V8: =IF(Q8<=0,0,IF(C8="Coniugati",IF(Q8>=Parametri!$B$61,Q8*Parametri!$B$62,VLOOKUP(Q8,Parametri!$A$47:$C$60,3,TRUE())+(Q8-VLOOKUP(Q8,Parametri!$A$47:$C$60,1,TRUE()))*VLOOKUP(Q8,Parametri!$A$47:$C$60,2,TRUE())),IF(Q8>=Parametri!$B$41,Q8*Parametri!$B$42,VLOOKUP(Q8,Parametri!$A$31:$C$40,3,TRUE())+(Q8-VLOOKUP(Q8,Parametri!$A$31:$C$40,1,TRUE()))*VLOOKUP(Q8,Parametri!$A$31:$C$40,2,TRUE())))) -> 0 | W8: =U8+V8 -> 0 | X8: =IF(F8>0,H8/F8,0) -> 0 | Y8: =H8-W8 -> 0 | Z8: =IF(B8="","",IF(B8="Residente TI",IF(F8>Parametri!$B$7,"SÌ (obbligatoria)","no"),"—")) | AA8: =IF(B8="","",IF(B8="Frontaliere nuovo accordo","TOU NON RICHIEDIBILE",IF(Y8>Parametri!$B$6,"TOU CONVIENE",IF(Y8<-Parametri!$B$6,"TOU NON CONVIENE","CIRCA NEUTRA"))))
N9: =E9*Parametri!$B$23 -> 0 | O9: =E9*Parametri!$B$24 -> 0 | P9: =MAX(0,G9-SUM(I9:M9)-N9) -> 0 | Q9: =MAX(0,G9-SUM(I9:M9)-O9) -> 0 | R9: =IF(P9<=0,0,IF(C9="Coniugati",IF(P9>=Parametri!$B$93,Parametri!$B$94,(VLOOKUP(P9,Parametri!$A$83:$C$92,3,TRUE())+(P9-VLOOKUP(P9,Parametri!$A$83:$C$92,1,TRUE()))*VLOOKUP(P9,Parametri!$A$83:$C$92,2,TRUE()))/P9),IF(P9>=Parametri!$B$77,Parametri!$B$78,(VLOOKUP(P9,Parametri!$A$67:$C$76,3,TRUE())+(P9-VLOOKUP(P9,Parametri!$A$67:$C$76,1,TRUE()))*VLOOKUP(P9,Parametri!$A$67:$C$76,2,TRUE()))/P9))) -> 0 | T9: =P9*IF(S9="",R9,S9) -> 0 | U9: =T9*(Parametri!$B$5+IFERROR(VLOOKUP(D9,Parametri!$A$12:$B$19,2,FALSE()),VLOOKUP("Altro",Parametri!$A$12:$B$19,2,FALSE())))/100 -> 0 | V9: =IF(Q9<=0,0,IF(C9="Coniugati",IF(Q9>=Parametri!$B$61,Q9*Parametri!$B$62,VLOOKUP(Q9,Parametri!$A$47:$C$60,3,TRUE())+(Q9-VLOOKUP(Q9,Parametri!$A$47:$C$60,1,TRUE()))*VLOOKUP(Q9,Parametri!$A$47:$C$60,2,TRUE())),IF(Q9>=Parametri!$B$41,Q9*Parametri!$B$42,VLOOKUP(Q9,Parametri!$A$31:$C$40,3,TRUE())+(Q9-VLOOKUP(Q9,Parametri!$A$31:$C$40,1,TRUE()))*VLOOKUP(Q9,Parametri!$A$31:$C$40,2,TRUE())))) -> 0 | W9: =U9+V9 -> 0 | X9: =IF(F9>0,H9/F9,0) -> 0 | Y9: =H9-W9 -> 0 | Z9: =IF(B9="","",IF(B9="Residente TI",IF(F9>Parametri!$B$7,"SÌ (obbligatoria)","no"),"—")) | AA9: =IF(B9="","",IF(B9="Frontaliere nuovo accordo","TOU NON RICHIEDIBILE",IF(Y9>Parametri!$B$6,"TOU CONVIENE",IF(Y9<-Parametri!$B$6,"TOU NON CONVIENE","CIRCA NEUTRA"))))
N10: =E10*Parametri!$B$23 -> 0 | O10: =E10*Parametri!$B$24 -> 0 | P10: =MAX(0,G10-SUM(I10:M10)-N10) -> 0 | Q10: =MAX(0,G10-SUM(I10:M10)-O10) -> 0 | R10: =IF(P10<=0,0,IF(C10="Coniugati",IF(P10>=Parametri!$B$93,Parametri!$B$94,(VLOOKUP(P10,Parametri!$A$83:$C$92,3,TRUE())+(P10-VLOOKUP(P10,Parametri!$A$83:$C$92,1,TRUE()))*VLOOKUP(P10,Parametri!$A$83:$C$92,2,TRUE()))/P10),IF(P10>=Parametri!$B$77,Parametri!$B$78,(VLOOKUP(P10,Parametri!$A$67:$C$76,3,TRUE())+(P10-VLOOKUP(P10,Parametri!$A$67:$C$76,1,TRUE()))*VLOOKUP(P10,Parametri!$A$67:$C$76,2,TRUE()))/P10))) -> 0 | T10: =P10*IF(S10="",R10,S10) -> 0 | U10: =T10*(Parametri!$B$5+IFERROR(VLOOKUP(D10,Parametri!$A$12:$B$19,2,FALSE()),VLOOKUP("Altro",Parametri!$A$12:$B$19,2,FALSE())))/100 -> 0 | V10: =IF(Q10<=0,0,IF(C10="Coniugati",IF(Q10>=Parametri!$B$61,Q10*Parametri!$B$62,VLOOKUP(Q10,Parametri!$A$47:$C$60,3,TRUE())+(Q10-VLOOKUP(Q10,Parametri!$A$47:$C$60,1,TRUE()))*VLOOKUP(Q10,Parametri!$A$47:$C$60,2,TRUE())),IF(Q10>=Parametri!$B$41,Q10*Parametri!$B$42,VLOOKUP(Q10,Parametri!$A$31:$C$40,3,TRUE())+(Q10-VLOOKUP(Q10,Parametri!$A$31:$C$40,1,TRUE()))*VLOOKUP(Q10,Parametri!$A$31:$C$40,2,TRUE())))) -> 0 | W10: =U10+V10 -> 0 | X10: =IF(F10>0,H10/F10,0) -> 0 | Y10: =H10-W10 -> 0 | Z10: =IF(B10="","",IF(B10="Residente TI",IF(F10>Parametri!$B$7,"SÌ (obbligatoria)","no"),"—")) | AA10: =IF(B10="","",IF(B10="Frontaliere nuovo accordo","TOU NON RICHIEDIBILE",IF(Y10>Parametri!$B$6,"TOU CONVIENE",IF(Y10<-Parametri!$B$6,"TOU NON CONVIENE","CIRCA NEUTRA"))))
N11: =E11*Parametri!$B$23 -> 0 | O11: =E11*Parametri!$B$24 -> 0 | P11: =MAX(0,G11-SUM(I11:M11)-N11) -> 0 | Q11: =MAX(0,G11-SUM(I11:M11)-O11) -> 0 | R11: =IF(P11<=0,0,IF(C11="Coniugati",IF(P11>=Parametri!$B$93,Parametri!$B$94,(VLOOKUP(P11,Parametri!$A$83:$C$92,3,TRUE())+(P11-VLOOKUP(P11,Parametri!$A$83:$C$92,1,TRUE()))*VLOOKUP(P11,Parametri!$A$83:$C$92,2,TRUE()))/P11),IF(P11>=Parametri!$B$77,Parametri!$B$78,(VLOOKUP(P11,Parametri!$A$67:$C$76,3,TRUE())+(P11-VLOOKUP(P11,Parametri!$A$67:$C$76,1,TRUE()))*VLOOKUP(P11,Parametri!$A$67:$C$76,2,TRUE()))/P11))) -> 0 | T11: =P11*IF(S11="",R11,S11) -> 0 | U11: =T11*(Parametri!$B$5+IFERROR(VLOOKUP(D11,Parametri!$A$12:$B$19,2,FALSE()),VLOOKUP("Altro",Parametri!$A$12:$B$19,2,FALSE())))/100 -> 0 | V11: =IF(Q11<=0,0,IF(C11="Coniugati",IF(Q11>=Parametri!$B$61,Q11*Parametri!$B$62,VLOOKUP(Q11,Parametri!$A$47:$C$60,3,TRUE())+(Q11-VLOOKUP(Q11,Parametri!$A$47:$C$60,1,TRUE()))*VLOOKUP(Q11,Parametri!$A$47:$C$60,2,TRUE())),IF(Q11>=Parametri!$B$41,Q11*Parametri!$B$42,VLOOKUP(Q11,Parametri!$A$31:$C$40,3,TRUE())+(Q11-VLOOKUP(Q11,Parametri!$A$31:$C$40,1,TRUE()))*VLOOKUP(Q11,Parametri!$A$31:$C$40,2,TRUE())))) -> 0 | W11: =U11+V11 -> 0 | X11: =IF(F11>0,H11/F11,0) -> 0 | Y11: =H11-W11 -> 0 | Z11: =IF(B11="","",IF(B11="Residente TI",IF(F11>Parametri!$B$7,"SÌ (obbligatoria)","no"),"—")) | AA11: =IF(B11="","",IF(B11="Frontaliere nuovo accordo","TOU NON RICHIEDIBILE",IF(Y11>Parametri!$B$6,"TOU CONVIENE",IF(Y11<-Parametri!$B$6,"TOU NON CONVIENE","CIRCA NEUTRA"))))
N12: =E12*Parametri!$B$23 -> 0 | O12: =E12*Parametri!$B$24 -> 0 | P12: =MAX(0,G12-SUM(I12:M12)-N12) -> 0 | Q12: =MAX(0,G12-SUM(I12:M12)-O12) -> 0 | R12: =IF(P12<=0,0,IF(C12="Coniugati",IF(P12>=Parametri!$B$93,Parametri!$B$94,(VLOOKUP(P12,Parametri!$A$83:$C$92,3,TRUE())+(P12-VLOOKUP(P12,Parametri!$A$83:$C$92,1,TRUE()))*VLOOKUP(P12,Parametri!$A$83:$C$92,2,TRUE()))/P12),IF(P12>=Parametri!$B$77,Parametri!$B$78,(VLOOKUP(P12,Parametri!$A$67:$C$76,3,TRUE())+(P12-VLOOKUP(P12,Parametri!$A$67:$C$76,1,TRUE()))*VLOOKUP(P12,Parametri!$A$67:$C$76,2,TRUE()))/P12))) -> 0 | T12: =P12*IF(S12="",R12,S12) -> 0 | U12: =T12*(Parametri!$B$5+IFERROR(VLOOKUP(D12,Parametri!$A$12:$B$19,2,FALSE()),VLOOKUP("Altro",Parametri!$A$12:$B$19,2,FALSE())))/100 -> 0 | V12: =IF(Q12<=0,0,IF(C12="Coniugati",IF(Q12>=Parametri!$B$61,Q12*Parametri!$B$62,VLOOKUP(Q12,Parametri!$A$47:$C$60,3,TRUE())+(Q12-VLOOKUP(Q12,Parametri!$A$47:$C$60,1,TRUE()))*VLOOKUP(Q12,Parametri!$A$47:$C$60,2,TRUE())),IF(Q12>=Parametri!$B$41,Q12*Parametri!$B$42,VLOOKUP(Q12,Parametri!$A$31:$C$40,3,TRUE())+(Q12-VLOOKUP(Q12,Parametri!$A$31:$C$40,1,TRUE()))*VLOOKUP(Q12,Parametri!$A$31:$C$40,2,TRUE())))) -> 0 | W12: =U12+V12 -> 0 | X12: =IF(F12>0,H12/F12,0) -> 0 | Y12: =H12-W12 -> 0 | Z12: =IF(B12="","",IF(B12="Residente TI",IF(F12>Parametri!$B$7,"SÌ (obbligatoria)","no"),"—")) | AA12: =IF(B12="","",IF(B12="Frontaliere nuovo accordo","TOU NON RICHIEDIBILE",IF(Y12>Parametri!$B$6,"TOU CONVIENE",IF(Y12<-Parametri!$B$6,"TOU NON CONVIENE","CIRCA NEUTRA"))))
